Workbook
Name EXRATE: '⚙️ 配置'!$B$6
Name EXRATE: '[1]⚙️ 配置'!$B$6
Name EXRATE: '[2]⚙️ 配置'!$B$6
Name FOB_WGS_001: '🎁 套件FOB'!$E$19
Name FOB_WGS_002: '🎁 套件FOB'!$E$35
Name FOB_WGS_003: '🎁 套件FOB'!$E$51
Name FOB_WGS_004: '🎁 套件FOB'!$E$67
Name FOB_WGS_005: '🎁 套件FOB'!$E$83
Name FOB_WGS_006: '🎁 套件FOB'!$E$99
Name FOB_WGS_007: '🎁 套件FOB'!$E$115
Name FOB_WGS_008: '🎁 套件FOB'!$E$132
Name FREIGHT_CBM: '⚙️ 配置'!$B$9
Name FREIGHT_CBM: '[1]⚙️ 配置'!$B$9
Name INS_RATE: '⚙️ 配置'!$B$11
Name INS_RATE: '[1]⚙️ 配置'!$B$11
Name INS_RATE: #REF!
Name LCL_MIN: '⚙️ 配置'!$B$10
Name LCL_MIN: '[1]⚙️ 配置'!$B$10
Name LCL_MIN: #REF!
Name MARKUP: '⚙️ 配置'!$B$8
Name MARKUP: '[1]⚙️ 配置'!$B$8
Name VATRATE: '⚙️ 配置'!$B$7
Name VATRATE: '[1]⚙️ 配置'!$B$7
Name VATRATE: #REF!

Sheet ⚙️ 配置
A1: Wischos 报价计算器 — 全局配置
A3: 说明： | B3: 黄色背景蓝字 = 你需要填的输入；黑字 = 自动计算；不要直接编辑黑字单元格
A5: 🌐 全局参数
A6: USD/RMB 汇率 | B6: 6.77 | C6: USD/RMB
A7: VAT 退税率 | B7: 0.13 | C7: 百分比（出口退税）
A8: SOHO 加价 % | B8: 0.25 | C8: 在直接成本上加价（建议 25-35%）
A9: 海运费率 USD/CBM | B9: 120 | C9: Shanghai LCL → 主要港口
A10: LCL 最低费 USD | B10: 120 | C10: 通常 1 CBM 起算
A11: 保险费率 | B11: 0.001 | C11: 货值的 0.1%
A12: CCPIT FTA 证书 RMB | B12: 200 | C12: 每票分摊（按总数量分）
A13: Logo 制版费 USD | B13: 50 | C13: 每个 SKU 一次性，分摊到订单
A14: ⚠️ 2026-06-09 提醒：港口费 (C列) 和 内陆派送 (E列) 是 AI 估算，浮动可能 30-50%。关税率 (D列) 和 GST/VAT (F列) 是查证过的官方数据。使用前请用询价模板向货代要真实报价。
A16: 🌍 各国 DDP 参数
A17: 国家代码 | B17: 国家名 | C17: 港口费 USD/票 ⚠️估算 | D17: 关税率（FTA） | E17: 内陆派送 USD/票 ⚠️估算 | F17: GST/VAT 率
A18: AU | B18: Australia (ChAFTA) | C18: 280 | D18: 0 | E18: 100 | F18: 0.1
A19: NZ | B19: New Zealand (NZ-China FTA) | C19: 282 | D19: 0 | E19: 96 | F19: 0.15
A20: SG | B20: Singapore (CSFTA) | C20: 200 | D20: 0 | E20: 60 | F20: 0.09
A21: AE | B21: UAE (No FTA) | C21: 250 | D21: 0.05 | E21: 80 | F21: 0.05
A22: HK | B22: Hong Kong (CEPA) | C22: 180 | D22: 0 | E22: 50 | F22: 0
A23: CH | B23: Switzerland (CN-CH FTA) | C23: 320 | D23: 0 | E23: 130 | F23: 0.081
A24: GB | B24: United Kingdom (No FTA) | C24: 300 | D24: 0.04 | E24: 110 | F24: 0.2
A25: SA | B25: Saudi Arabia (No FTA) | C25: 260 | D25: 0.05 | E25: 90 | F25: 0.15

Sheet 📦 单品成本
A1: 单品成本表 — 从 1688 含税价自动计算 USD
A3: 说明： | B3: C 列填 1688 含税单价（RMB）→ 后面列全自动算。F 列 logo 工艺加价可调（默认 0.30 USD）。
A5: SKU | B5: 产品名 | C5: 不税单价(RMB) | D5: 专票税点 | E5: 含税单价(RMB) | F5: USD 等价 | G5: Logo 工艺加价(USD) | H5: 单品总成本(USD) | I5: 备注
A6: WP-101 | B6: Brass Crown Bolt-Action Pen | C6: 29 | D6: 0.1 | E6: =C6*(1+D6) -> 31.9 | F6: =E6/'⚙️ 配置'!EXRATE -> 4.7119645 | G6: 0.3 | H6: =F6+G6 -> 5.0119645 | I6: 激光雕刻
A7: WP-102 | B7: Executive Dual-Head Inkless Pen | C7: 11 | D7: 0.1 | E7: =C7*(1+D7) -> 12.1 | F7: =E7/'⚙️ 配置'!EXRATE -> 1.7872969 | G7: 0.3 | H7: =F7+G7 -> 2.0872969 | I7: 铝阳极氧化无墨笔
A8: WP-103 | B8: Tactical Stainless Pen | C8: 33 | D8: 0.1 | E8: =C8*(1+D8) -> 36.3 | F8: =E8/'⚙️ 配置'!EXRATE -> 5.3618907 | G8: 0.4 | H8: =F8+G8 -> 5.7618907 | I8: 303 不锈钢战术
A9: WP-104 | B9: 6-in-1 Tool Pen | C9: 8 | D9: 0.1 | E9: =C9*(1+D9) -> 8.8 | F9: =E9/'⚙️ 配置'!EXRATE -> 1.2998523 | G9: 0.3 | H9: =F9+G9 -> 1.5998523 | I9: 锌合金多功能
A10: WP-105 | B10: Artisan Brass Rollerball | C10: 10 | D10: 0.1 | E10: =C10*(1+D10) -> 11 | F10: =E10/'⚙️ 配置'!EXRATE -> 1.6248154 | G10: 0.3 | H10: =F10+G10 -> 1.9248154 | I10: 黄铜走珠笔
A11: WP-106 | B11: Solid Brass Ballpoint Pen | C11: 15 | D11: 0.1 | E11: =C11*(1+D11) -> 16.5 | F11: =E11/'⚙️ 配置'!EXRATE -> 2.437223 | G11: 0.3 | H11: =F11+G11 -> 2.737223 | I11: 黄铜圆珠笔
A12: WP-107 | B12: hexagonal brass click pen | C12: 22 | D12: 0.1 | E12: =C12*(1+D12) -> 24.2 | F12: =E12/'⚙️ 配置'!EXRATE -> 3.5745938 | G12: 0.3 | H12: =F12+G12 -> 3.8745938 | I12: 激光雕刻
A13: WP-108 | B13: Solid Brass Bolt-Action Pen | C13: 25 | D13: 0.1 | E13: =C13*(1+D13) -> 27.5 | F13: =E13/'⚙️ 配置'!EXRATE -> 4.0620384 | G13: 0.3 | H13: =F13+G13 -> 4.3620384 | I13: 激光雕刻
A14: WP-201 | B14: Aluminium Mouse Pad | C14: 25 | D14: 0.1 | E14: =C14*(1+D14) -> 27.5 | F14: =E14/'⚙️ 配置'!EXRATE -> 4.0620384 | G14: 0.3 | H14: =F14+G14 -> 4.3620384 | I14: 5052 铝合金
A15: WP-202 | B15: Precision Aluminium Pen Holder | C15: 22 | D15: 0.1 | E15: =C15*(1+D15) -> 24.2 | F15: =E15/'⚙️ 配置'!EXRATE -> 3.5745938 | G15: 0.3 | H15: =F15+G15 -> 3.8745938 | I15: 6061-T6 铝
A16: WP-203 | B16: Zinc Alloy Letter Opener | C16: 12 | D16: 0.1 | E16: =C16*(1+D16) -> 13.2 | F16: =E16/'⚙️ 配置'!EXRATE -> 1.9497784 | G16: 0.3 | H16: =F16+G16 -> 2.2497784 | I16: 电镀锌合金
A17: WP-204 | B17: Propeller Spinning Letter Opener | C17: 26 | D17: 0.1 | E17: =C17*(1+D17) -> 28.6 | F17: =E17/'⚙️ 配置'!EXRATE -> 4.2245199 | G17: 0.4 | H17: =F17+G17 -> 4.6245199 | I17: 机械螺旋
... A33: WP-404 | B33: Bamboo-Pattern Stainless Mug | C33: 8.8 | D33: 0.1 | E33: =C33*(1+D33) -> 9.68 | F33: =E33/'⚙️ 配置'!EXRATE -> 1.4298375 | G33: 0.4 | H33: =F33+G33 -> 1.8298375 | I33: 不锈钢竹纹（纯钢）
A34: WP-405 | B34: Ice-Crystal Pure Titanium Egg Cup | C34: 35 | D34: 0.1 | E34: =C34*(1+D34) -> 38.5 | F34: =E34/'⚙️ 配置'!EXRATE -> 5.6868538 | G34: 0.4 | H34: =F34+G34 -> 6.0868538
A35: WP-406 | B35: Pure Titanium Capsule Bottle | C35: 30 | D35: 0.1 | E35: =C35*(1+D35) -> 33 | F35: =E35/'⚙️ 配置'!EXRATE -> 4.8744461 | G35: 0.4 | H35: =F35+G35 -> 5.2744461 | I35: 300ML
A36: WP-407 | B36: Double-Wall Stainless Desk Cup | C36: 6.5 | D36: 0.1 | E36: =C36*(1+D36) -> 7.15 | F36: =E36/'⚙️ 配置'!EXRATE -> 1.05613 | G36: 0.4 | H36: =F36+G36 -> 1.45613 | I36: 不锈钢双层桌杯
A37: WP-408 | B37: Titanium Tea Infuser Cup | C37: 57 | D37: 0.1 | E37: =C37*(1+D37) -> 62.7 | F37: =E37/'⚙️ 配置'!EXRATE -> 9.2614476 | G37: 0.5 | H37: =F37+G37 -> 9.7614476 | I37: 钛茶滤杯 480ml

Sheet 🎁 套件FOB
A1: 套件 FOB 成本计算 — 8 个套件，每个独立块
A2: ⚠️ 2026-06-09 更新：每个套件新增 4 项成本（🆕橙色行 = 国内运费/包装人工/外箱/品牌印刷物），默认 0。你后期根据询价/真实情况填入数据，FOB 自动重算。SOHO 加价已自动包含这 4 项。
A3: 说明： | B3: 组件 USD 自动从「单品成本」表 VLOOKUP；包装费 / 一次性费 / 加价% 来自配置表。FOB 自动计算。
A5: WGS-001 · The Desk Starter
A6: SKU | B6: 产品名 | C6: 单品 USD（来自单品成本表） | D6: 数量 | E6: 小计 USD
A7: WP-102 | B7: Inkless 笔 | C7: =VLOOKUP(A7,'📦 单品成本'!$A$6:$H$50,8,FALSE()) -> 2.0872969 | D7: 1 | E7: =C7*D7 -> 2.0872969
A8: WP-203 | B8: 锌开信刀 | C8: =VLOOKUP(A8,'📦 单品成本'!$A$6:$H$50,8,FALSE()) -> 2.2497784 | D8: 1 | E8: =C8*D8 -> 2.2497784
A9: WP-205 | B9: 金属书签 | C9: =VLOOKUP(A9,'📦 单品成本'!$A$6:$H$50,8,FALSE()) -> 1.1124077 | D9: 1 | E9: =C9*D9 -> 1.1124077
B10: 组件合计 (USD) | E10: =SUM(E7:E9) -> 5.449483
B11: 包装：Drawer Rigid Box + EVA [基于网搜真实数据 — 待询价确认] | E11: 1.8
B12: 🆕 国内运费分摊（工厂→打包仓→上海港） | E12: 0
B13: 🆕 包装人工（拆包/分装/封盒/贴标） | E13: 0
B14: 🆕 外箱+内填充（出口纸箱/气泡膜） | E14: 0
B15: 🆕 品牌印刷物（cert卡/说明书/吊牌，可选） | E15: 0
B16: 其他：CCPIT 证书 + 单证 + QC（每套分摊） | E16: 1.3
B17: 直接成本合计 (USD) | E17: =E10+E11+E12+E13+E14+E15+E16 -> 8.549483
B18: + SOHO 加价（仅 加在 组件+包装+4 新增项 上） | E18: =(E10+E11+E12+E13+E14+E15)*'⚙️ 配置'!MARKUP -> 1.8123708
B19: ★ FOB Shanghai per set (USD) | E19: =E17+E18 -> 10.361854
A21: WGS-002 · The Mechanical Desk
A22: SKU | B22: 产品名 | C22: 单品 USD（来自单品成本表） | D22: 数量 | E22: 小计 USD
A23: WP-101 | B23: 黄铜螺旋笔 | C23: =VLOOKUP(A23,'📦 单品成本'!$A$6:$H$50,8,FALSE()) -> 5.0119645 | D23: 1 | E23: =C23*D23 -> 5.0119645
A24: WP-204 | B24: 螺旋开信刀 | C24: =VLOOKUP(A24,'📦 单品成本'!$A$6:$H$50,8,FALSE()) -> 4.6245199 | D24: 1 | E24: =C24*D24 -> 4.6245199
A25: WP-208 | B25: 折叠铝支架 | C25: =VLOOKUP(A25,'📦 单品成本'!$A$6:$H$50,8,FALSE()) -> 4.7870015 | D25: 1 | E25: =C25*D25 -> 4.7870015
B26: 组件合计 (USD) | E26: =SUM(E23:E25) -> 14.423486
B27: 包装：Magnetic Box + EVA + Foil [基于网搜真实数据 — 待询价确认] | E27: 3.2
B28: 🆕 国内运费分摊（工厂→打包仓→上海港） | E28: 0
B29: 🆕 包装人工（拆包/分装/封盒/贴标） | E29: 0
B30: 🆕 外箱+内填充（出口纸箱/气泡膜） | E30: 0
B31: 🆕 品牌印刷物（cert卡/说明书/吊牌，可选） | E31: 0
B32: 其他：CCPIT 证书 + 单证 + QC（每套分摊） | E32: 1.3
B33: 直接成本合计 (USD) | E33: =E26+E27+E28+E29+E30+E31+E32 -> 18.923486
B34: + SOHO 加价（仅 加在 组件+包装+4 新增项 上） | E34: =(E26+E27+E28+E29+E30+E31)*'⚙️ 配置'!MARKUP -> 4.4058715
B35: ★ FOB Shanghai per set (USD) | E35: =E33+E34 -> 23.329357
A37: WGS-003 · The Pocket Three
A38: SKU | B38: 产品名 | C38: 单品 USD（来自单品成本表） | D38: 数量 | E38: 小计 USD
A39: WP-302 | B39: 黄铜钥匙器 | C39: =VLOOKUP(A39,'📦 单品成本'!$A$6:$H$50,8,FALSE()) -> 0.81994092 | D39: 1 | E39: =C39*D39 -> 0.81994092
A40: WP-303 | B40: 不锈钢钱夹 | C40: =VLOOKUP(A40,'📦 单品成本'!$A$6:$H$50,8,FALSE()) -> 0.78744461 | D40: 1 | E40: =C40*D40 -> 0.78744461
A41: WP-304 | B41: 钛梳 | C41: =VLOOKUP(A41,'📦 单品成本'!$A$6:$H$50,8,FALSE()) -> 4.3620384 | D41: 1 | E41: =C41*D41 -> 4.3620384
B42: 组件合计 (USD) | E42: =SUM(E39:E41) -> 5.9694239
B43: 包装：Tin Box [基于网搜真实数据 — 待询价确认] | E43: 1.8
...

Sheet 💰 完整报价
A1: 完整报价表 — 选套件 + 数量 + 目的国 = 一键得 FOB / CIF / DDP
A3: 说明： | B3: 黄色单元格自己改：套件、数量、目的国。其他数字全部自动算。
A5: 🎯 输入参数 | D5: 📦 套件 CBM 参考表（可调）
A6: 选择套件 | B6: WGS-001 | D6: SKU | E6: CBM/set | F6: Weight/Carton
A7: 订单数量（套） | B7: 100 | D7: WGS-001 | E7: =灵活外箱!F17 -> 0.057 | F7: =灵活外箱!H17 -> 15.5
A8: 目的国家 | B8: NZ | D8: WGS-002 | E8: =灵活外箱!F18 -> 0.057 | F8: =灵活外箱!H18 -> 14
D9: WGS-003 | E9: =灵活外箱!F19 -> 0.046 | F9: =灵活外箱!H19 -> 12.5
D10: WGS-004 | E10: =灵活外箱!F20 -> 0.067 | F10: =灵活外箱!H20 -> 15
D11: WGS-005 | E11: =灵活外箱!F21 -> 0.059 | F11: =灵活外箱!H21 -> 12
D12: WGS-006 | E12: =灵活外箱!F22 -> 0.059 | F12: =灵活外箱!H22 -> 14
D13: WGS-007 | E13: =灵活外箱!F23 -> 0.074 | F13: =灵活外箱!H23 -> 14.5
D14: WGS-008 | E14: =灵活外箱!F24 -> 0.071 | F14: =灵活外箱!H24 -> 14
A19: 📊 计算结果
A20: FOB per set (USD) | B20: =INDIRECT("FOB_" & SUBSTITUTE(B6,"-","_")) -> 10.361854 | D20: 📋 订单总价
A21: CBM per set | B21: =VLOOKUP(B6,D7:E23,2,FALSE()) -> 0.057 | D21: 报价方式 | E21: 单价 (USD) | F21: 订单总价 (USD)
A22: 总 CBM（含 30% 出口缓冲） | B22: =B21*B7*1.3 -> 7.41 | D22: FOB Shanghai | E22: =B20 -> 10.361854 | F22: =B20*B7 -> 1036.1854
A23: 海运费（USD，总） | B23: =MAX(B22*FREIGHT_CBM, LCL_MIN) -> 889.2 | D23: CIF Destination | E23: =B27 -> 19.264216 | F23: =B27*B7 -> 1926.4216
A24: 海运费 per set | B24: =B23/B7 -> 8.892 | D24: DDP ex-GST | E24: =B34 -> 23.044216 | F24: =B34*B7 -> 2304.4216
A25: 货值 per set | B25: =B20 -> 10.361854 | D25: DDP 含 GST | E25: =B36 -> 26.500848 | F25: =B36*B7 -> 2650.0848
A26: 保险 per set | B26: =B25*INS_RATE -> 0.010361854
A27: CIF per set (USD) | B27: =B20+B24+B26 -> 19.264216
A28: 港口费 (USD，总) | B28: =VLOOKUP(B8,'⚙️ 配置'!$A$18:$F$25,3,FALSE()) -> 282
A29: 港口费 per set | B29: =B28/B7 -> 2.82
A30: 关税率（按 FTA） | B30: =VLOOKUP(B8,'⚙️ 配置'!$A$18:$F$25,4,FALSE()) -> 0
A31: 关税 per set | B31: =B27*B30 -> 0
A32: 内陆派送 (USD，总) | B32: =VLOOKUP(B8,'⚙️ 配置'!$A$18:$F$25,5,FALSE()) -> 96
A33: 内陆派送 per set | B33: =B32/B7 -> 0.96
A34: DDP per set ex-GST (USD) | B34: =B27+B29+B31+B33 -> 23.044216
A35: GST/VAT 率 | B35: =VLOOKUP(B8,'⚙️ 配置'!$A$18:$F$25,6,FALSE()) -> 0.15
A36: DDP per set 含 GST (USD) | B36: =B34*(1+B35) -> 26.500848
A38: 📝 说明 / 假设：
A39: 1. FOB / CIF / DDP 都是 SOHO 加价后的售价（含你的毛利）
A40: 2. DDP ex-GST 是行业标准 B2B 报价（GST 由买家退税回收）
A41: 3. DDP 含 GST 适合"全包到门"报价（用于直接面向终端 / 政府）
A42: 4. 100 套是小批量，500+ 套时直接成本会下降 15-25%
A43: 5. 改 ⚙️ 配置 的"SOHO 加价 %"可整体调整报价利润
A44: 6. 改 📦 单品成本 的「含税单价 RMB」列可更新实际工厂报价

Sheet 灵活外箱
A1: Flexible Export Carton Plan | B1: Flexible Export Carton Plan | C1: Flexible Export Carton Plan | D1: Flexible Export Carton Plan | E1: Flexible Export Carton Plan | F1: Flexible Export Carton Plan | G1: Flexible Export Carton Plan | H1: Flexible Export Carton Plan | I1: Flexible Export Carton Plan | J1: Flexible Export Carton Plan | K1: Flexible Export Carton Plan | L1: Flexible Export Carton Plan
A2: Different carton sizes per set. Best for air/express, smaller mixed orders, and lower dimensional-weight waste. | B2: Different carton sizes per set. Best for air/express, smaller mixed orders, and lower dimensional-weight waste. | C2: Different carton sizes per set. Best for air/express, smaller mixed orders, and lower dimensional-weight waste. | D2: Different carton sizes per set. Best for air/express, smaller mixed orders, and lower dimensional-weight waste. | E2: Different carton sizes per set. Best for air/express, smaller mixed orders, and lower dimensional-weight waste. | F2: Different carton sizes per set. Best for air/express, smaller mixed orders, and lower dimensional-weight waste. | G2: Different carton sizes per set. Best for air/express, smaller mixed orders, and lower dimensional-weight waste. | H2: Different carton sizes per set. Best for air/express, smaller mixed orders, and lower dimensional-weight waste. | I2: Different carton sizes per set. Best for air/express, smaller mixed orders, and lower dimensional-weight waste. | J2: Different carton sizes per set. Best for air/express, smaller mixed orders, and lower dimensional-weight waste. | K2: Different carton sizes per set. Best for air/express, smaller mixed orders, and lower dimensional-weight waste. | L2: Different carton sizes per set. Best for air/express, smaller mixed orders, and lower dimensional-weight waste.
A4: Set | B4: Gift box size mm | C4: Packing layout | D4: Sets/carton | E4: Carton size mm | F4: CBM/carton | G4: Dim weight /5000 kg | H4: Gross weight/carton | I4: Carton min $ | J4: Carton max $ | K4: Carton cost/set min $ | L4: Carton cost/set max $
A5: WGS-001-3 | B5: 285 x 165 x 40 | C5: 2 x 3 x 4 layers | D5: 24 | E5: 610 x 520 x 180 | F5: 0.057 | G5: 11.4 | H5: 15-16kg | I5: 1.3 | J5: 2.2 | K5: 0.05 | L5: 0.09
A6: WGS-002-3 | B6: 295 x 230 x 50 | C6: 2 x 2 x 3 layers | D6: 12 | E6: 610 x 520 x 180 | F6: 0.057 | G6: 11.4 | H6: 13-14.5kg | I6: 1.3 | J6: 2.2 | K6: 0.11 | L6: 0.18
A7: WGS-003-3 | B7: 200 x 190 x 38 | C7: 3 x 2 x 4 layers | D7: 24 | E7: 610 x 420 x 180 | F7: 0.046 | G7: 9.2 | H7: 11-13kg | I7: 1.1 | J7: 1.8 | K7: 0.05 | L7: 0.08
A8: WGS-004-3 | B8: 240 x 180 x 45 | C8: 3 x 2 x 4 layers | D8: 24 | E8: 610 x 520 x 210 | F8: 0.067 | G8: 13.3 | H8: 14-16.5kg | I8: 1.4 | J8: 2.4 | K8: 0.06 | L8: 0.1
A9: WGS-005-3 | B9: 255 x 205 x 75 | C9: 2 x 2 x 3 layers | D9: 12 | E9: 540 x 440 x 250 | F9: 0.059 | G9: 11.9 | H9: 11.5-13kg | I9: 1.4 | J9: 2.3 | K9: 0.12 | L9: 0.19
A10: WGS-006-3 | B10: 330 x 230 x 105 | C10: 1 x 2 x 3 layers | D10: 6 | E10: 480 x 360 x 340 | F10: 0.059 | G10: 11.8 | H10: 12-14.5kg | I10: 1.6 | J10: 2.6 | K10: 0.27 | L10: 0.43
A11: WGS-007-3 | B11: 280 x 230 x 115 | C11: 2 x 2 x 2 layers | D11: 8 | E11: 590 x 490 x 255 | F11: 0.074 | G11: 14.7 | H11: 13-15.5kg | I11: 1.7 | J11: 2.8 | K11: 0.21 | L11: 0.35
A12: WGS-008-4 | B12: 360 x 290 x 90 | C12: 1 x 2 x 3 layers | D12: 6 | E12: 610 x 390 x 300 | F12: 0.071 | G12: 14.3 | H12: 13.5-15.5kg | I12: 1.8 | J12: 3 | K12: 0.3 | L12: 0.5
A15: 测算用
A16: Set | B16: Gift box size mm | C16: Packing layout | D16: Sets/carton | E16: Carton size mm | F16: CBM/carton | G16: Dim weight /5000 kg | H16: Gross weight/carton | I16: Carton min $ | J16: Carton max $ | K16: Carton cost/set min $ | L16: Carton cost/set max $
A17: WGS-001-3 | B17: 285 x 165 x 40 | C17: 2 x 3 x 4 layers | D17: 24 | E17: 610 x 520 x 180 | F17: 0.057 | G17: 11.4 | H17: 15.5 | I17: 1.3 | J17: 2.2 | K17: 0.05 | L17: 0.09
A18: WGS-002-3 | B18: 295 x 230 x 50 | C18: 2 x 2 x 3 layers | D18: 12 | E18: 610 x 520 x 180 | F18: 0.057 | G18: 11.4 | H18: 14 | I18: 1.3 | J18: 2.2 | K18: 0.11 | L18: 0.18
A19: WGS-003-3 | B19: 200 x 190 x 38 | C19: 3 x 2 x 4 layers | D19: 24 | E19: 610 x 420 x 180 | F19: 0.046 | G19: 9.2 | H19: 12.5 | I19: 1.1 | J19: 1.8 | K19: 0.05 | L19: 0.08
A20: WGS-004-3 | B20: 240 x 180 x 45 | C20: 3 x 2 x 4 layers | D20: 24 | E20: 610 x 520 x 210 | F20: 0.067 | G20: 13.3 | H20: 15 | I20: 1.4 | J20: 2.4 | K20: 0.06 | L20: 0.1
A21: WGS-005-3 | B21: 255 x 205 x 75 | C21: 2 x 2 x 3 layers | D21: 12 | E21: 540 x 440 x 250 | F21: 0.059 | G21: 11.9 | H21: 12 | I21: 1.4 | J21: 2.3 | K21: 0.12 | L21: 0.19
A22: WGS-006-3 | B22: 330 x 230 x 105 | C22: 1 x 2 x 3 layers | D22: 6 | E22: 480 x 360 x 340 | F22: 0.059 | G22: 11.8 | H22: 14 | I22: 1.6 | J22: 2.6 | K22: 0.27 | L22: 0.43
A23: WGS-007-3 | B23: 280 x 230 x 115 | C23: 2 x 2 x 2 layers | D23: 8 | E23: 590 x 490 x 255 | F23: 0.074 | G23: 14.7 | H23: 14.5 | I23: 1.7 | J23: 2.8 | K23: 0.21 | L23: 0.35
A24: WGS-008-4 | B24: 360 x 290 x 90 | C24: 1 x 2 x 3 layers | D24: 6 | E24: 610 x 390 x 300 | F24: 0.071 | G24: 14.3 | H24: 14 | I24: 1.8 | J24: 3 | K24: 0.3 | L24: 0.5
