Workbook
Name EXRATE: '⚙️ 配置'!$B$6
Name FOB_WGS_001: '🎁 套件FOB'!$E$15
Name FOB_WGS_002: '🎁 套件FOB'!$E$27
Name FOB_WGS_003: '🎁 套件FOB'!$E$39
Name FOB_WGS_004: '🎁 套件FOB'!$E$51
Name FOB_WGS_005: '🎁 套件FOB'!$E$63
Name FOB_WGS_006: '🎁 套件FOB'!$E$75
Name FOB_WGS_007: '🎁 套件FOB'!$E$87
Name FOB_WGS_008: '🎁 套件FOB'!$E$100
Name FREIGHT_CBM: '⚙️ 配置'!$B$9
Name INS_RATE: '⚙️ 配置'!$B$11
Name LCL_MIN: '⚙️ 配置'!$B$10
Name MARKUP: '⚙️ 配置'!$B$8
Name VATRATE: '⚙️ 配置'!$B$7

Sheet ⚙️ 配置
A1: Wischos 报价计算器 — 全局配置
A3: 说明： | B3: 黄色背景蓝字 = 你需要填的输入；黑字 = 自动计算；不要直接编辑黑字单元格
A5: 🌐 全局参数
A6: USD/RMB 汇率 | B6: 6.77 | C6: USD/RMB
A7: VAT 退税率 | B7: 0.13 | C7: 百分比（出口退税）
A8: SOHO 加价 % | B8: 0.3 | C8: 在直接成本上加价（建议 25-35%）
A9: 海运费率 USD/CBM | B9: 120 | C9: Shanghai LCL → 主要港口
A10: LCL 最低费 USD | B10: 120 | C10: 通常 1 CBM 起算
A11: 保险费率 | B11: 0.001 | C11: 货值的 0.1%
A12: CCPIT FTA 证书 RMB | B12: 200 | C12: 每票分摊（按总数量分）
A13: Logo 制版费 USD | B13: 50 | C13: 每个 SKU 一次性，分摊到订单
A16: 🌍 各国 DDP 参数
A17: 国家代码 | B17: 国家名 | C17: 港口费 USD/票 | D17: 关税率（FTA） | E17: 内陆派送 USD/票 | F17: GST/VAT 率
A18: AU | B18: Australia (ChAFTA) | C18: 280 | D18: 0 | E18: 100 | F18: 0.1
A19: NZ | B19: New Zealand (NZ-China FTA) | C19: 282 | D19: 0 | E19: 96 | F19: 0.15
A20: SG | B20: Singapore (CSFTA) | C20: 200 | D20: 0 | E20: 60 | F20: 0.09
A21: AE | B21: UAE (No FTA) | C21: 250 | D21: 0.05 | E21: 80 | F21: 0.05
A22: HK | B22: Hong Kong (CEPA) | C22: 180 | D22: 0 | E22: 50 | F22: 0
A23: CH | B23: Switzerland (CN-CH FTA) | C23: 320 | D23: 0 | E23: 130 | F23: 0.077
A24: GB | B24: United Kingdom (No FTA) | C24: 300 | D24: 0.04 | E24: 110 | F24: 0.2
A25: SA | B25: Saudi Arabia (No FTA) | C25: 260 | D25: 0.05 | E25: 90 | F25: 0.15

Sheet 💰 完整报价
A1: 完整报价表 — 选套件 + 数量 + 目的国 = 一键得 FOB / CIF / DDP
A3: 说明： | B3: 黄色单元格自己改：套件、数量、目的国。其他数字全部自动算。
A5: 🎯 输入参数 | D5: 📦 套件 CBM 参考表（可调）
A6: 选择套件 | B6: WGS-001 | D6: SKU | E6: CBM/set | F6: 说明
A7: 订单数量（套） | B7: 100 | D7: WGS-001 | E7: 0.00225 | F7: Drawer box
A8: 目的国家 | B8: NZ | D8: WGS-002 | E8: 0.00247 | F8: Magnetic + Stand
D9: WGS-003 | E9: 0.0015 | F9: Tin box
A10: 📊 计算结果
A11: FOB per set (USD) | B11: =INDIRECT("FOB_" & SUBSTITUTE(B6,"-","_")) -> 11.778108 | D11: 📋 订单总价
A12: CBM per set | B12: =VLOOKUP(B6,D7:E14,2,FALSE()) -> 0.00225 | D12: 报价方式 | E12: 单价 (USD) | F12: 订单总价 (USD)
A13: 总 CBM（含 30% 出口缓冲） | B13: =B12*B7*1.3 -> 0.2925 | D13: FOB Shanghai | E13: =B11 -> 11.778108 | F13: =B11*B7 -> 1177.8108
A14: 海运费（USD，总） | B14: =MAX(B13*FREIGHT_CBM, LCL_MIN) -> 120 | D14: CIF Destination | E14: =B18 -> 12.989886 | F14: =B18*B7 -> 1298.9886
A15: 海运费 per set | B15: =B14/B7 -> 1.2 | D15: DDP ex-GST | E15: =B25 -> 16.769886 | F15: =B25*B7 -> 1676.9886
A16: 货值 per set | B16: =B11 -> 11.778108 | D16: DDP 含 GST | E16: =B27 -> 19.285369 | F16: =B27*B7 -> 1928.5369
A17: 保险 per set | B17: =B16*INS_RATE -> 0.011778108
A18: CIF per set (USD) | B18: =B11+B15+B17 -> 12.989886
A19: 港口费 (USD，总) | B19: =VLOOKUP(B8,'⚙️ 配置'!$A$18:$F$25,3,FALSE()) -> 282
A20: 港口费 per set | B20: =B19/B7 -> 2.82
A21: 关税率（按 FTA） | B21: =VLOOKUP(B8,'⚙️ 配置'!$A$18:$F$25,4,FALSE()) -> 0
A22: 关税 per set | B22: =B18*B21 -> 0
A23: 内陆派送 (USD，总) | B23: =VLOOKUP(B8,'⚙️ 配置'!$A$18:$F$25,5,FALSE()) -> 96
A24: 内陆派送 per set | B24: =B23/B7 -> 0.96
A25: DDP per set ex-GST (USD) | B25: =B18+B20+B22+B24 -> 16.769886
A26: GST/VAT 率 | B26: =VLOOKUP(B8,'⚙️ 配置'!$A$18:$F$25,6,FALSE()) -> 0.15
A27: DDP per set 含 GST (USD) | B27: =B25*(1+B26) -> 19.285369
A29: 📝 说明 / 假设：
A30: 1. FOB / CIF / DDP 都是 SOHO 加价后的售价（含你的毛利）
A31: 2. DDP ex-GST 是行业标准 B2B 报价（GST 由买家退税回收）
A32: 3. DDP 含 GST 适合"全包到门"报价（用于直接面向终端 / 政府）
A33: 4. 100 套是小批量，500+ 套时直接成本会下降 15-25%
A34: 5. 改 ⚙️ 配置 的"SOHO 加价 %"可整体调整报价利润
A35: 6. 改 📦 单品成本 的「含税单价 RMB」列可更新实际工厂报价

Sheet 📦 单品成本
A1: 单品成本表 — 从 1688 含税价自动计算 USD
A3: 说明： | B3: C 列填 1688 含税单价（RMB）→ 后面列全自动算。F 列 logo 工艺加价可调（默认 0.30 USD）。
A5: SKU | B5: 产品名 | C5: 含税单价(RMB) | D5: 不含税(RMB) | E5: USD 等价 | F5: Logo 工艺加价(USD) | G5: 单品总成本(USD) | H5: 备注
A6: WP-101 | B6: Brass Crown Bolt-Action Pen | C6: 50 | D6: =C6/(1+VATRATE) -> 44.247788 | E6: =D6/EXRATE -> 6.5358623 | F6: 0.4 | G6: =E6+F6 -> 6.9358623 | H6: 黄铜螺旋机械
A7: WP-102 | B7: Executive Dual-Head Inkless Pen | C7: 11 | D7: =C7/(1+VATRATE) -> 9.7345133 | E7: =D7/EXRATE -> 1.4378897 | F7: 0.3 | G7: =E7+F7 -> 1.7378897 | H7: 铝阳极氧化无墨笔
A8: WP-103 | B8: Tactical Stainless Pen | C8: 45 | D8: =C8/(1+VATRATE) -> 39.823009 | E8: =D8/EXRATE -> 5.882276 | F8: 0.4 | G8: =E8+F8 -> 6.282276 | H8: 303 不锈钢战术
A9: WP-104 | B9: 6-in-1 Tool Pen | C9: 38 | D9: =C9/(1+VATRATE) -> 33.628319 | E9: =D9/EXRATE -> 4.9672553 | F9: 0.4 | G9: =E9+F9 -> 5.3672553 | H9: 锌合金多功能
A10: WP-105 | B10: Artisan Brass Rollerball | C10: 55 | D10: =C10/(1+VATRATE) -> 48.672566 | E10: =D10/EXRATE -> 7.1894485 | F10: 0.4 | G10: =E10+F10 -> 7.5894485 | H10: 黄铜走珠笔
A11: WP-106 | B11: Solid Brass Ballpoint Pen | C11: 52 | D11: =C11/(1+VATRATE) -> 46.017699 | E11: =D11/EXRATE -> 6.7972968 | F11: 0.4 | G11: =E11+F11 -> 7.1972968 | H11: 黄铜圆珠笔
A12: WP-201 | B12: Aluminium Mouse Pad | C12: 65 | D12: =C12/(1+VATRATE) -> 57.522124 | E12: =D12/EXRATE -> 8.496621 | F12: 0.3 | G12: =E12+F12 -> 8.796621 | H12: 5052 铝合金
A13: WP-202 | B13: Precision Aluminium Pen Holder | C13: 45 | D13: =C13/(1+VATRATE) -> 39.823009 | E13: =D13/EXRATE -> 5.882276 | F13: 0.3 | G13: =E13+F13 -> 6.182276 | H13: 6061-T6 铝
A14: WP-203 | B14: Zinc Alloy Letter Opener | C14: 12 | D14: =C14/(1+VATRATE) -> 10.619469 | E14: =D14/EXRATE -> 1.5686069 | F14: 0.3 | G14: =E14+F14 -> 1.8686069 | H14: 电镀锌合金
A15: WP-204 | B15: Propeller Spinning Letter Opener | C15: 58 | D15: =C15/(1+VATRATE) -> 51.327434 | E15: =D15/EXRATE -> 7.5816002 | F15: 0.4 | G15: =E15+F15 -> 7.9816002 | H15: 机械螺旋
A16: WP-205 | B16: Custom Metal Bookmark | C16: 5 | D16: =C16/(1+VATRATE) -> 4.4247788 | E16: =D16/EXRATE -> 0.65358623 | G16: =E16+F16 -> 0.65358623 | H16: 含异形开模分摊
A17: WP-206 | B17: Precision Brass Spinning Top | C17: 42 | D17: =C17/(1+VATRATE) -> 37.168142 | E17: =D17/EXRATE -> 5.4901243 | F17: 0.3 | G17: =E17+F17 -> 5.7901243 | H17: 黄铜陀螺
A18: WP-207 | B18: Carbon Fiber Magnetic Fidget Stick | C18: 35 | D18: =C18/(1+VATRATE) -> 30.973451 | E18: =D18/EXRATE -> 4.5751036 | F18: 0.3 | G18: =E18+F18 -> 4.8751036 | H18: 碳纤维+磁铁（边缘 SKU）
A19: WP-208 | B19: Folding Aluminium Device Stand | C19: 52 | D19: =C19/(1+VATRATE) -> 46.017699 | E19: =D19/EXRATE -> 6.7972968 | F19: 0.4 | G19: =E19+F19 -> 7.1972968 | H19: 6061-T6 折叠
A20: WP-301 | B20: RFID Aluminium Badge Holder | C20: 40 | D20: =C20/(1+VATRATE) -> 35.39823 | E20: =D20/EXRATE -> 5.2286898 | F20: 0.3 | G20: =E20+F20 -> 5.5286898 | H20: 铝合金 RFID
A21: WP-302 | B21: Industrial Brass Key Organizer | C21: 32 | D21: =C21/(1+VATRATE) -> 28.318584 | E21: =D21/EXRATE -> 4.1829519 | F21: 0.3 | G21: =E21+F21 -> 4.4829519 | H21: 黄铜钥匙器
A22: WP-303 | B22: Stainless Steel Money Clip | C22: 22 | D22: =C22/(1+VATRATE) -> 19.469027 | E22: =D22/EXRATE -> 2.8757794 | F22: 0.3 | G22: =E22+F22 -> 3.1757794 | H22: 不锈钢钱夹
A23: WP-304 | B23: Titanium EDC Comb | C23: 25 | D23: =C23/(1+VATRATE) -> 22.123894 | E23: =D23/EXRATE -> 3.2679311 | F23: 0.3 | G23: =E23+F23 -> 3.5679311 | H23: 钛梳
A24: WP-305 | B24: Mini EDC Pry Bar | C24: 18 | D24: =C24/(1+VATRATE) -> 15.929204 | E24: =D24/EXRATE -> 2.3529104 | F24: 0.3 | G24: =E24+F24 -> 2.6529104 | H24: 不锈钢/钛撬棒
A25: WP-307 | B25: EDC Folding Scissors | C25: 26 | D25: =C25/(1+VATRATE) -> 23.00885 | E25: =D25/EXRATE -> 3.3986484 | F25: 0.3 | G25: =E25+F25 -> 3.6986484 | H25: 2CR13 折叠剪
A26: WP-308 | B26: Titanium EDC Keychain/Carabiner | C26: 38 | D26: =C26/(1+VATRATE) -> 33.628319 | E26: =D26/EXRATE -> 4.9672553 | F26: 0.4 | G26: =E26+F26 -> 5.3672553 | H26: 钛+黄铜锁芯
A27: WP-309 | B27: Slim Push Business Card Case | C27: 35 | D27: =C27/(1+VATRATE) -> 30.973451 | E27: =D27/EXRATE -> 4.5751036 | F27: 0.4 | G27: =E27+F27 -> 4.9751036 | H27: 不锈钢推拉卡盒
A28: WP-401 | B28: Pure Titanium Vacuum Bottle (large) | C28: 180 | D28: =C28/(1+VATRATE) -> 159.29204 | E28: =D28/EXRATE -> 23.529104 | F28: 0.5 | G28: =E28+F28 -> 24.029104 | H28: 纯钛真空瓶
... A33: WP-408 | B33: Titanium Tea Infuser Cup | C33: 110 | D33: =C33/(1+VATRATE) -> 97.345133 | E33: =D33/EXRATE -> 14.378897 | F33: 0.5 | G33: =E33+F33 -> 14.878897 | H33: 钛茶滤杯 480ml

Sheet 🎁 套件FOB
A1: 套件 FOB 成本计算 — 8 个套件，每个独立块
A3: 说明： | B3: 组件 USD 自动从「单品成本」表 VLOOKUP；包装费 / 一次性费 / 加价% 来自配置表。FOB 自动计算。
A5: WGS-001 · The Desk Starter
A6: SKU | B6: 产品名 | C6: 单品 USD（来自单品成本表） | D6: 数量 | E6: 小计 USD
A7: WP-102 | B7: Inkless 笔 | C7: =VLOOKUP(A7,'📦 单品成本'!$A$6:$G$50,7,FALSE()) -> 1.7378897 | D7: 1 | E7: =C7*D7 -> 1.7378897
A8: WP-203 | B8: 锌开信刀 | C8: =VLOOKUP(A8,'📦 单品成本'!$A$6:$G$50,7,FALSE()) -> 1.8686069 | D8: 1 | E8: =C8*D8 -> 1.8686069
A9: WP-205 | B9: 金属书签 | C9: =VLOOKUP(A9,'📦 单品成本'!$A$6:$G$50,7,FALSE()) -> 0.65358623 | D9: 1 | E9: =C9*D9 -> 0.65358623
B10: 组件合计 (USD) | E10: =SUM(E7:E9) -> 4.2600829
B11: 包装：Drawer Rigid Box + EVA | E11: 3.5
B12: 其他：CCPIT 证书 + 单证 + QC（每套分摊） | E12: 1.3
B13: 直接成本合计 (USD) | E13: =E10+E11+E12 -> 9.0600829
B14: + SOHO 加价 (来自配置) | E14: =E13*MARKUP -> 2.7180249
B15: ★ FOB Shanghai per set (USD) | E15: =E13+E14 -> 11.778108
A17: WGS-002 · The Mechanical Desk
A18: SKU | B18: 产品名 | C18: 单品 USD（来自单品成本表） | D18: 数量 | E18: 小计 USD
A19: WP-101 | B19: 黄铜螺旋笔 | C19: =VLOOKUP(A19,'📦 单品成本'!$A$6:$G$50,7,FALSE()) -> 6.9358623 | D19: 1 | E19: =C19*D19 -> 6.9358623
A20: WP-204 | B20: 螺旋开信刀 | C20: =VLOOKUP(A20,'📦 单品成本'!$A$6:$G$50,7,FALSE()) -> 7.9816002 | D20: 1 | E20: =C20*D20 -> 7.9816002
A21: WP-208 | B21: 折叠铝支架 | C21: =VLOOKUP(A21,'📦 单品成本'!$A$6:$G$50,7,FALSE()) -> 7.1972968 | D21: 1 | E21: =C21*D21 -> 7.1972968
B22: 组件合计 (USD) | E22: =SUM(E19:E21) -> 22.114759
B23: 包装：Magnetic Box + EVA + Foil | E23: 5.5
B24: 其他：CCPIT 证书 + 单证 + QC（每套分摊） | E24: 1.3
B25: 直接成本合计 (USD) | E25: =E22+E23+E24 -> 28.914759
B26: + SOHO 加价 (来自配置) | E26: =E25*MARKUP -> 8.6744278
B27: ★ FOB Shanghai per set (USD) | E27: =E25+E26 -> 37.589187
A29: WGS-003 · The Pocket Three
A30: SKU | B30: 产品名 | C30: 单品 USD（来自单品成本表） | D30: 数量 | E30: 小计 USD
A31: WP-302 | B31: 黄铜钥匙器 | C31: =VLOOKUP(A31,'📦 单品成本'!$A$6:$G$50,7,FALSE()) -> 4.4829519 | D31: 1 | E31: =C31*D31 -> 4.4829519
A32: WP-303 | B32: 不锈钢钱夹 | C32: =VLOOKUP(A32,'📦 单品成本'!$A$6:$G$50,7,FALSE()) -> 3.1757794 | D32: 1 | E32: =C32*D32 -> 3.1757794
A33: WP-304 | B33: 钛梳 | C33: =VLOOKUP(A33,'📦 单品成本'!$A$6:$G$50,7,FALSE()) -> 3.5679311 | D33: 1 | E33: =C33*D33 -> 3.5679311
B34: 组件合计 (USD) | E34: =SUM(E31:E33) -> 11.226662
B35: 包装：Tin Box | E35: 3
B36: 其他：CCPIT 证书 + 单证 + QC（每套分摊） | E36: 1.3
B37: 直接成本合计 (USD) | E37: =E34+E35+E36 -> 15.526662
B38: + SOHO 加价 (来自配置) | E38: =E37*MARKUP -> 4.6579987
B39: ★ FOB Shanghai per set (USD) | E39: =E37+E38 -> 20.184661
A41: WGS-004 · The Field EDC
A42: SKU | B42: 产品名 | C42: 单品 USD（来自单品成本表） | D42: 数量 | E42: 小计 USD
A43: WP-103 | B43: 战术不锈钢笔 | C43: =VLOOKUP(A43,'📦 单品成本'!$A$6:$G$50,7,FALSE()) -> 6.282276 | D43: 1 | E43: =C43*D43 -> 6.282276
A44: WP-305 | B44: 撬棒 | C44: =VLOOKUP(A44,'📦 单品成本'!$A$6:$G$50,7,FALSE()) -> 2.6529104 | D44: 1 | E44: =C44*D44 -> 2.6529104
A45: WP-307 | B45: 折叠剪 | C45: =VLOOKUP(A45,'📦 单品成本'!$A$6:$G$50,7,FALSE()) -> 3.6986484 | D45: 1 | E45: =C45*D45 -> 3.6986484
...
